Workbook

Sheet MIU Login Details
A1: No. | B1: Surname | C1: First name | D1: Password | E1: Type
A2: 1 | B2: Masasanya | C2: Thabile Nicole | D2: Masasanya615456 | E2: Guest
A3: 2 | B3: Buthelezi | C3: Prudence Anne | D3: Buthelezi619383 | E3: Guest
A4: 3 | B4: Gambushe | C4: Vuyi | D4: Gambushe 619384 | E4: Guest
A5: 4 | B5: Hlatshwayo | C5: Lwazi | D5: Hlatshwayo619385 | E5: Guest
A6: 5 | B6: Januarie | C6: Nomathemba | D6: Januarie619386 | E6: Guest
A7: 6 | B7: Kotane | C7: Retshego Goitseone | D7: Kotane619387 | E7: Guest
A8: 7 | B8: Lebea | C8: Lebohang | D8: Lebea619388 | E8: Guest
A9: 8 | B9: Lekganyane | C9: Molatela Suzan | D9: Lekganyane619389 | E9: Guest
A10: 9 | B10: Lengoati | C10: Phumelela Love Langaelihle | D10: Lengoati619390 | E10: Guest
A11: 10 | B11: Lephoto | C11: Refilwe | D11: Lephoto619391 | E11: Guest
A12: 11 | B12: Lepyana | C12: Nyaduwa | D12: Lepyana619392 | E12: Guest
A13: 12 | B13: Maake | C13: Lethabo Jocobeth | D13: Maake619393 | E13: Guest
... A57: 56 | B57: Zibonti | C57: Zingisa | D57: Zibonti618954 | E57: Guest

Sheet Student List
A1: No | B1: Group | C1: Location | D1: Surname | E1: First Name | F1: Second & Third Name | G1: Full Name on Diploma upon Graduation | H1: Emails | I1: MIU Emails | J1: MII | K1: MIU ID | L1: Whatsapp Number
A2: 1 | B2: N | D2: Masasanya | E2: Thabile | F2: Nicole | G2: Thabile Nicole Masasanya | H2: masasanya.thabile@maharishinstitute.org | I2: nicole.masasanya@miu.edu | J2: 615456 | K2: 615456 | L2: 0719496467
A3: 2 | B3: S | D3: Buthelezi | E3: Prudence | F3: Anne | G3: Prudence Anne BUTHELEZI | H3: prudence.buthelezi@maharishinstitute.org | I3: pbuthelezi@miu.edu | J3: 619383 | K3: 017009 | L3: 0643049430
A4: 3 | B4: S | C4: D | D4: Gambushe | E4: Vuyi | G4: Vuyi GAMBUSHE | H4: gambushev@maharishinstitute.org | I4: vgambushe@miu.edu | J4: 619384 | K4: 018752 | L4: 084 841 0015
A5: 4 | B5: S | D5: Hlatshwayo | E5: Lwazi | G5: Lwazi HLATSHWAYO | H5: lwazi.hlatshwayo@maharishinstitute.org | I5: lhlatshwayo@miu.edu | J5: 619385 | K5: 017029 | L5: 062 474 7455
A6: 5 | B6: S | D6: Januarie | E6: Nomathemba | G6: Nomathemba JANUARIE | H6: nomathemba.januarie@maharishinstitute.org | I6: njanuarie@miu.edu | J6: 619386 | K6: 017032 | L6: 081 519 5881
A7: 6 | B7: S | D7: Kotane | E7: Retshego | F7: Goitseone | G7: Retshego Goitseone KOTANE | H7: retshego.kotane18@maharishinstitute.org | I7: rkotane@miu.edu | J7: 619389 | K7: 018054 | L7: 0764701495
A8: 7 | B8: S | D8: Lebea | E8: Lebohang | G8: Lebohang LEBEA | H8: lebogang.lebea@maharishinstitute.org | I8: llebea@miu.edu | J8: 619388 | K8: 017519 | L8: 060 354 3965 | M8: Bryte Student
A9: 8 | B9: S | D9: Lekganyane | E9: Molatela | F9: Suzan | G9: Molatela Suzan LEKGANYANE | H9: molatela.lekganyane@maharishinstitute.org | I9: mlekganyane@miu.edu | J9: 619389 | K9: 017282 | L9: 0664398620
A10: 9 | B10: S | D10: Lengoati | E10: Phumelela | F10: Love Langaelihle | G10: Phumelela Love Langaelihle LENGOATI | H10: phemelela.lengoati18@maharishinstitute.org | I10: plengoati@miu.edu | J10: 619390 | K10: 018335 | L10: 079 414 5202
A11: 10 | B11: S | D11: Lepyana | E11: Nyaduwa | G11: Nyaduwa LEPYANA | H11: nyaduwa.lepyana@maharishinstitute.org | I11: nlepyana@miu | J11: 019392 | K11: 017055 | L11: 0812151973
A12: 11 | B12: S | D12: Maake | E12: Lethabo | F12: Jocobeth | G12: Lethabo Jocobeth MAAKE | H12: lethabo.maake@maharishinstitute.org | I12: lmaake@miu.edu | J12: 619393 | K12: 017061 | L12: 066 504 5641
A13: 12 | B13: S | D13: Magwasha | E13: Tshimangadzo | F13: Mercy | G13: Tshimangadzo Mercy MAGWASHA | H13: tshimangadzo.magwasha18@maharishinstitute.org | I13: tmagwasha@miu.edu | J13: 619394 | K13: 018093 | L13: 0726781756
A14: 13 | B14: S | D14: Makhabane | E14: Josephina | F14: Tshepiso Mookho | G14: Josephina Tshepiso Mookho MAKHABANE | H14: tshepiso.makhabane@maharishinstitute.org | I14: jmakhabane@miu.edu | J14: 619396 | K14: 017084 | L14: 0789089859
A15: 14 | B15: S | D15: Makhafola | E15: Kamogelo | F15: Bridget | G15: kamogelo Bridget MAKHAFOLA | H15: kamogelo.makhafola18@maharishinstitute.org | I15: kmakhafola@miu.edu | J15: 619397 | K15: 018103 | L15: 0606 77 1084
A16: 15 | B16: S | D16: Makhafola | E16: Lerato | F16: Precious | G16: Lerato Precious MAKHAFOLA | H16: lerato.makhafola18@maharishinstitute.org | I16: lmakhafola@miu.edu | J16: 619398 | K16: 018102 | L16: 0820885195
A17: 16 | B17: S | D17: Mangane | E17: Lebogang | F17: Emily | G17: Lebogang Emily MANGANE | H17: lebogang.mangane@maharishinstitute.org | I17: lmangane@miu.edu | J17: 619399 | K17: 15253 | L17: 064 039 5896
A18: 17 | B18: S | D18: Masemola | E18: Gopolang | F18: Celia | G18: Gopolang Celia MASEMOLA | H18: gopolang.masemola18@maharishinstitute.org | I18: gmasemola@miu.edu | J18: 619400 | K18: 018114 | L18: 0717499053
A19: 18 | B19: S | D19: Mashapa | E19: Morongwa | F19: Titelo | G19: Morongwa Titelo MASHAPA | H19: morongwa.mashapa18@maharishinstitute.org | I19: mmashapa@miu.edu | J19: 619401 | K19: 017533 | L19: 0660137718
A20: 19 | B20: S | D20: Mbatha | E20: Anele | F20: Snenhlanhla | G20: Anele Snenhlanhla MBATHA | H20: anele.Mbatha18@maharishinstitute.org | I20: ambatha@miu.edu | J20: 619402 | K20: 018136 | L20: 071 255 7836
A21: 20 | B21: S | D21: Mhlongo | E21: Floyd | G21: Floyd MHLONGO | H21: floyd.mhlongo18@maharishinstitute.org | I21: fmhlongo@miu.edu | J21: 619403 | K21: 018323 | L21: 0792802919
A22: 21 | B22: S | D22: Mndwetywa | E22: Yamkelani | F22: Sisipho | G22: Yamekelani Sisipho MNDWETYWA | H22: yamkelani.mtilwa@maharishinstitute.org | I22: ymndwetywa@miu.edu | J22: 619404 | K22: 017156 | L22: 067 056 8932 | M22: Bryte Student
A23: 22 | B23: S | D23: Moema | E23: Boitshoko | F23: Elsie | G23: Boitshoko Elsie MOEMA | H23: boitshoko.moema@maharishinstitute.org | I23: bmoema@miu | J23: 619405 | K23: 017125 | L23: 0790392649
A24: 23 | B24: S | D24: Molaletsa | E24: Karabo | F24: William | G24: Karabo William MOLALETSA | H24: karabo.molaletsa@maharishinstitute.org | I24: kmolaletsa@miu.edu | J24: 619406 | K24: 017554 | L24: 067 816 7233 | M24: Bryte Student
A25: 24 | B25: S | D25: Monametsi | E25: Refilwe | G25: Refilwe MONAMETSI | H25: refilwe.monametsi@maharishinstitute.org | I25: rmonametsi@miu.edu | J25: 619407 | K25: 15103 | L25: 0810362015
A26: 25 | B26: S | D26: More | E26: Molebatsi | F26: Lucas | G26: Molebatsi Lucas MORE | H26: molebatsi.More18@maharishinstitute.org | I26: mmore@miu.edu | J26: 619408 | K26: 15103 | L26: 078 998 6785
A27: 26 | B27: S | D27: Motimele | E27: Tshegofatso | F27: Tsolaka | G27: Tshegofatso Tsolaka MOTIMELE | H27: tshegofatso.motimele@maharishinstitute.org | I27: tmotimele@miu.edu | J27: 619409 | K27: 17141 | L27: 073 986 9830 | M27: Bryte Student
A28: 27 | B28: S | D28: Mthethwa | E28: Sanele | F28: Millicent | G28: Sanele Millicent MTHETHWA | H28: sanele.mthethwa@maharishinstitute.org | I28: smthethwa@miu.edu | J28: 619410 | K28: 17155 | L28: 073 926 9931
A29: 28 | B29: S | D29: Mtshakazi | E29: Vuyolwethu | G29: Vuyolwethu MTSHAKAZI | H29: vuyolwethu.mtshakazi@maharishinstitute.org | I29: vmtshakazi@miu.edu | J29: 619411 | K29: 17157 | L29: 078 798 7160
A30: 29 | B30: S | D30: Nawa | E30: Ontlametse | F30: Keoagile | G30: Ontlametse Keoagile NAWA | H30: ontlametse.nawa18@maharishinstitute.org | I30: onawa@miu.edu | J30: 619412 | K30: 18186 | L30: 0606270780
A31: 30 | B31: S | D31: Ncube | E31: Thembisile | F31: Sbongiseni | G31: Thembisile Sbongiseni NCUBE | H31: thembisile.ncube@maharishinstitute.org | I31: tncube@miu.edu | J31: 619413 | K31: 017163 | L31: 067 273 7929
A32: 31 | B32: S | D32: Ndaba | E32: Aobakwe | F32: Solomon | G32: Aobakwe Solomon NDABA | H32: solomon.ndaba@maharishinstitute.org | I32: andaba@miu.edu | J32: 619414 | K32: 17290 | L32: 065 669 5128
A33: 32 | B33: S | C33: D | D33: Ndaba | E33: Ncinci | F33: Vumile | G33: Ncinci Vumile NDABA | H33: ndabav@maharishinstitute.org | I33: nndaba@miu.edu | J33: 619415 | K33: 18763 | L33: 079 793 6449
A34: 33 | B34: S | D34: Ndlela | E34: Princess | F34: Thandeka | G34: Princess Thandeka NDLELA | H34: princess.ndlela@maharishinstitute.org | I34: pndlela@miu.edu | J34: 619416 | K34: 17170 | L34: 069 506 2124
A35: 34 | B35: S | D35: Ndou | E35: Sedzani | F35: Cynthia | G35: Sedzani Cynthia NDOU | H35: sedzani.ndou@maharishinstitute.org | I35: sndou@miu.edu | J35: 618941 | K35: 17176 | L35: 0637206409 | M35: Absa
A36: 35 | B36: S | C36: D | D36: Ngcobo | E36: Hlengiwe | F36: Pretty | G36: Hlengiwe Pretty NGCOBO | H36: ngcoboh@maharishinstitute.org | I36: hngcobo@miu.edu | J36: 619417 | K36: 18765 | L36: 071 079 8362
A37: 36 | B37: S | D37: Nhlabathi | E37: Kuku | F37: Bridget | G37: Kuku Bridget NHLABATHI | H37: kuku.Nhlabathi18@maharishinstitute.org | I37: knhlabathi@miu.edu | J37: 619148 | K37: 18207 | L37: 0678093809
A38: 37 | B38: S | D38: Nkawule | E38: Unathi | G38: Unathi NKAWULE | H38: unathi.nkawule18@maharishinstitute.org | I38: unkawule@miu.edu | J38: 619419 | K38: 18209 | L38: 083 857 0796
A39: 38 | B39: S | D39: Nkosi | E39: Thobeka | G39: Thobeka NKOSI | H39: thobeka.nkosi@maharishinstitute.org | I39: tnkosi@miu.edu | J39: 619420 | K39: 17201 | L39: 068 746 6428 | M39: Bryte Student
A40: 39 | B40: S | D40: Nokane | E40: Bertha | F40: Gomolemo | G40: Bertha Gomolemo NOKANE | H40: bertha.Nokane18@maharishinstitute.org | I40: bnokane@miu.edu | J40: 619421 | K40: 18217 | L40: 0631943129
...

Sheet Learnership
A2: No | B2: Surname | C2: Name | D2: Location | E2: Degree Sponsor | F2: MII Department | G2: External Partner | H2: Vertical Stream | I2: Learnership Start | J2: Learnership End | K2: Contract ended /Student not doing anything | L2: CV in PDF Format | M2: Work-readiness CV-preparation | N2: Work-readiness Interview Skills | O2: Mock Interviews | P2: Students joined GMI: Yes/No ? | Q2: Comments
A3: 1 | B3: Buthelezi | C3: Prudence | E3: No sponsor | F3: Foundation phase TA | G3: Absa-Ended | I3: 46054 | J3: 46418 | L3: Yes | M3: Yes | N3: Yes | O3: Yes
A4: 2 | B4: Gambushe | C4: Vuyi | D4: D | E4: YES Program: ITC Info-Tech | F4: Consciousness Department | I4: 46050 | J4: 46722
A5: 3 | B5: Hlatshwayo | C5: Lwazi | E5: Moshal | F5: Work Study-Skills | G5: Absa-Ended | I5: 46054 | J5: 46371 | L5: Yes | M5: No | N5: Yes | O5: Yes
A6: 4 | B6: Januarie | C6: Nomathemba | E6: Nahana | F6: MII Foundation phase | I6: 46049 | J6: 46414 | L6: Yes | M6: Yes
A7: 5 | B7: Kotane | C7: Retshego | E7: Nahana | F7: MII Work study -Adminstration department | I7: 46237 | J7: 46599
A8: 6 | B8: Lebea | C8: Lebohang | E8: Manpower | F8: Skills | G8: Bryte | I8: 1 Novembber 2022 | J8: 46446 | L8: Yes | M8: Yes | N8: Yes
A9: 7 | B9: Lekganyane | C9: Molatela | E9: Stefanutti Stocks | F9: YES program{ Foundation Adminstration Department} | G9: German | I9: 46204 | J9: 46568
A10: 8 | B10: Lengoati | C10: Phumelela | F10: No learnership /Work study | I10: - | J10: -
A11: 9 | B11: Lephoto | C11: Refilwe | E11: Stefanutti Stocks | F11: Yes program(Skills) | I11: 1 Aprril 2025 | J11: 46203 | K11: Contract ended
A12: 10 | B12: Lepyana | C12: Nyaduwa | E12: Moshal | F12: Work Study - Marketing Department | G12: Absa-Ended | I12: 45964 | J12: 46359 | L12: Yes
A13: 11 | B13: Maake | C13: Lethabo | E13: Bryte | F13: Yes Program(Skills) | I13: 45717 | J13: 46203 | K13: Contract ended
A14: 12 | B14: Magwasha | C14: Tshimangadzo | E14: Nahana | F14: Work Study - Admin Assistant | G14: Foundation department | I14: 46023 | J14: 46357 | N14: Yes
A15: 13 | B15: Makhabane | C15: Josephina | E15: No sponsor | F15: No learnership /Work study | G15: Bryte (Ended) | I15: - | J15: - | L15: Yes | M15: Yes | N15: Yes
A16: 14 | B16: Makhafola | C16: Kamogelo | E16: Moshal | F16: Learnership DYICT | I16: 46082 | J16: 46446
A17: 15 | B17: Makhafola | C17: Lerato | E17: Moshal | F17: Work Study - Foundation phase | I17: 46054 | J17: 46359
A18: 16 | B18: Mangane | C18: Lebogang | E18: No sponsor | F18: MII Foundation phase | I18: 46049 | J18: 46414 | L18: Yes | M18: Yes
A19: 17 | B19: Masemola | C19: Gopolang | E19: Nahana | F19: No learnership /Work study | I19: - | J19: -
A20: 18 | B20: Mashapa | C20: Morongwa | E20: Moshal | F20: YES program{ academic department} TA | I20: 46083 | J20: 46446 | M20: Yes
A21: 19 | B21: Mbatha | C21: Anele | E21: Nahana | F21: YES program{ Foundation Phase TA} | I21: 01 August 2026 | J21: 46598
A22: 20 | B22: Mhlongo | C22: Floyd | E22: Moshal | F22: YES program{ Consciousness department} | I22: 46235 | J22: 46598
A23: 21 | B23: Mndwetywa | C23: Yamkelani | E23: Nahana | F23: Skills | G23: Bryte | I23: 44866 | J23: 46446 | L23: Yes | M23: Yes | N23: Yes
A24: 22 | B24: Moema | C24: Boitshoko | E24: Moshal | F24: Work Study {Foundation Phase} | G24: Absa-Ended | I24: 46054 | J24: 46419 | L24: Yes | N24: Yes
A25: 23 | B25: Molaletsa | C25: Karabo | E25: Purple Group | F25: Skills | G25: Bryte | I25: 44866 | J25: 46446 | L25: Yes | M25: Yes | N25: Yes
A26: 24 | B26: Monametsi | C26: Refilwe | E26: No sponsor | F26: Consciousness Department | I26: 44927 | J26: 46203 | K26: Contract ended
A27: 25 | B27: More | C27: Molebatsi | E27: Moshal | F27: FMA {System Development } | I27: 46160 | J27: 46525
A28: 26 | B28: Motimele | C28: Tshegofatso | E28: No sponsor | F28: Skills | G28: Bryte | I28: 44866 | J28: 46446 | L28: Yes | M28: Yes | N28: Yes
A29: 27 | B29: Mthethwa | C29: Sanele | E29: Nahana | F29: Work Study { Foundation Phase} | I29: 45658 | J29: 46357
A30: 28 | B30: Mtshakazi | C30: Vuyolwethu | E30: Moshal | F30: No learnership /Work study | I30: - | J30: - | L30: Yes | O30: Yes
A31: 29 | B31: Nawa | C31: Ontlametse | E31: Moshal | F31: FMA | I31: 46160 | J31: 46525
A32: 30 | B32: Ncube | C32: Thembisile | E32: Stefanutti Stocks | F32: External Workstudy | I32: 46235 | J32: 46371 | L32: Yes | M32: No | N32: Yes | O32: Yes
A33: 31 | B33: Ndaba | C33: Aobakwe | E33: Stefanutti Stocks | F33: MII Work study Foundation phase | I33: 46049 | J33: 46414 | L33: Yes | M33: Yes | N33: Yes | O33: Yes
A34: 32 | B34: Ndaba | C34: Ncinci | D34: D | E34: YES Program: ITC Info-Tech | F34: Learnership {HR Assistant} | I34: 46062 | J34: 46418
A35: 33 | B35: Ndlela | C35: Princess | E35: No sponsor | F35: External Work study | I35: 46235 | J35: 46371 | L35: Yes
A36: 34 | B36: Ndou | C36: Sedzani | E36: Moshal | F36: Internship | G36: Absa | I36: 46113 | J36: 46447
A37: 35 | B37: Ngcobo | C37: Hlengiwe | D37: D | E37: Work-study | F37: Sewing Department | G37: WSS | I37: 46023 | J37: 46203 | K37: Contract ended
A38: 36 | B38: Nhlabathi | C38: Kuku | E38: Nahana | F38: Foundation phase TA | G38: Practicum ended | I38: 46600 | J38: 46598
A39: 37 | B39: Nkawule | C39: Unathi | E39: Nahana | F39: Practicum department | I39: 46235 | J39: 46598
A40: 38 | B40: Nkosi | C40: Thobeka | E40: Stefanutti Stocks | F40: Skills | G40: Bryte | I40: 1 Novembber 2022 | J40: 46446 | L40: Yes | M40: Yes | N40: Yes
A41: 39 | B41: Nokane | C41: Bertha | E41: Moshal | F41: YES program{ academic department} | I41: 45809 | J41: 46446
...

Sheet Absenteeism Summary Sheet
A1: Last Name | B1: First Name | C1: August 17-20 | D1: August 24-27 | E1: August 31-03 | F1: September 07-10 | G1: September 14-17 | H1: September 21-24 | I1: September 28-01 | J1: October 05-08 | K1: Total Absenteeism | L1: Comments
A2: Masasanya | B2: Thabile | C2: {=INDEX('August 17-20'!AD4:AD56,0)} -> 0 | D2: {=INDEX('August 24-27'!AE4:AE56,0)} -> 0 | E2: {=INDEX('August 31-03'!AD4:AD56,0)} -> 0 | F2: {=INDEX('September 07-10'!AD4:AD56,0)} -> 1 | G2: {=INDEX('September 14-17'!AD4:AD56,0)} -> 0 | H2: {=INDEX('September 21-24'!AD4:AD56,0)} -> 0 | I2: {=INDEX('September 28-01'!AD4:AD56,0)} -> 0 | J2: {=INDEX('October 05-08'!AD4:AD56,0)} -> 0 | K2: =SUM(C2:J2) -> 1
A3: Buthelezi | B3: Prudence | C3: 0 | D3: 0 | E3: 0 | F3: 0 | G3: 0 | H3: 0 | I3: 0 | J3: 0 | K3: =SUM(C3:J3) -> 0
A4: Gambushe | B4: Vuyi | C4: 0 | D4: 0 | E4: 0 | F4: 0 | G4: 1 | H4: 0 | I4: 0 | J4: 0 | K4: =SUM(C4:J4) -> 1
A5: Hlatshwayo | B5: Lwazi | C5: 0 | D5: 0 | E5: 0 | F5: 1 | G5: 0 | H5: 0 | I5: 0 | J5: 0 | K5: =SUM(C5:J5) -> 1
A6: Januarie | B6: Nomathemba | C6: 0 | D6: 0 | E6: 0 | F6: 1 | G6: 1 | H6: 0 | I6: 0 | J6: 0 | K6: =SUM(C6:J6) -> 2
A7: Kotane | B7: Retshego | C7: 0 | D7: 1 | E7: 0 | F7: 1 | G7: 0 | H7: 0 | I7: 0 | J7: 0 | K7: =SUM(C7:J7) -> 2
A8: Lebea | B8: Lebohang | C8: 0 | D8: 0 | E8: 0 | F8: 1 | G8: 0 | H8: 0 | I8: 0 | J8: 0 | K8: =SUM(C8:J8) -> 1
A9: Lekganyane | B9: Molatela | C9: 0 | D9: 0 | E9: 0 | F9: 0 | G9: 0 | H9: 0 | I9: 0 | J9: 0 | K9: =SUM(C9:J9) -> 0
A10: Lengoati | B10: Phumelela | C10: 0 | D10: 0 | E10: 1 | F10: 0 | G10: 0 | H10: 0 | I10: 0 | J10: 0 | K10: =SUM(C10:J10) -> 1
A11: Lepyana | B11: Nyaduwa | C11: 0 | D11: 1 | E11: 0 | F11: 0 | G11: 1 | H11: 0 | I11: 0 | J11: 0 | K11: =SUM(C11:J11) -> 2
A12: Maake | B12: Lethabo | C12: 0 | D12: 0 | E12: 0 | F12: 0 | G12: 1 | H12: 0 | I12: 0 | J12: 0 | K12: =SUM(C12:J12) -> 1
A13: Magwasha | B13: Tshimangadzo | C13: 0 | D13: 0 | E13: 0 | F13: 0 | G13: 0 | H13: 0 | I13: 0 | J13: 0 | K13: =SUM(C13:J13) -> 0
A14: Makhabane | B14: Josephina | C14: 1 | D14: 0 | E14: 1 | F14: 1 | G14: 1 | H14: 0 | I14: 0 | J14: 0 | K14: =SUM(C14:J14) -> 4
... A21: Mhlongo | B21: Floyd | C21: 0 | D21: 0 | E21: 0 | F21: 1 | G21: 1 | H21: 0 | I21: 0 | J21: 0 | K21: =SUM(C21:J21) -> 2
A22: Mndwetywa | B22: Yamkelani | C22: 1 | D22: 1 | E22: 0 | F22: 3 | G22: 0 | H22: 0 | I22: 0 | J22: 0 | K22: =SUM(C22:J22) -> 5 | L22: Email sent on the 09/09/2026 for absenteeism
A23: Moema | B23: Boitshoko | C23: 0 | D23: 0 | E23: 0 | F23: 1 | G23: 1 | H23: 0 | I23: 0 | J23: 0 | K23: =SUM(C23:J23) -> 2
A24: Molaletsa | B24: Karabo | C24: 1 | D24: 0 | E24: 0 | F24: 1 | G24: 0 | H24: 0 | I24: 0 | J24: 0 | K24: =SUM(C24:J24) -> 2
A25: Monametsi | B25: Refilwe | C25: 0 | D25: 0 | E25: 0 | F25: 0 | G25: 0 | H25: 0 | I25: 0 | J25: 0 | K25: =SUM(C25:J25) -> 0
A26: More | B26: Molebatsi | C26: 0 | D26: 1 | E26: 0 | F26: 0 | G26: 0 | H26: 0 | I26: 0 | J26: 0 | K26: =SUM(C26:J26) -> 1
A27: Motimele | B27: Tshegofatso | C27: 1 | D27: 0 | E27: 0 | F27: 1 | G27: 1 | H27: 0 | I27: 0 | J27: 0 | K27: =SUM(C27:J27) -> 3
A28: Mthethwa | B28: Sanele | C28: 0 | D28: 0 | E28: 1 | F28: 0 | G28: 0 | H28: 0 | I28: 0 | J28: 0 | K28: =SUM(C28:J28) -> 1
A29: Mtshakazi | B29: Vuyolwethu | C29: 2 | D29: 0 | E29: 0 | F29: 0 | G29: 0 | H29: 0 | I29: 0 | J29: 0 | K29: =SUM(C29:J29) -> 2
A30: Nawa | B30: Ontlametse | C30: 0 | D30: 0 | E30: 0 | F30: 0 | G30: 0 | H30: 0 | I30: 0 | J30: 0 | K30: =SUM(C30:J30) -> 0
A31: Ncube | B31: Thembisile | C31: 1 | D31: 0 | E31: 0 | F31: 2 | G31: 0 | H31: 0 | I31: 0 | J31: 0 | K31: =SUM(C31:J31) -> 3
A32: Ndaba | B32: Aobakwe | C32: 0 | D32: 0 | E32: 0 | F32: 1 | G32: 2 | H32: 0 | I32: 0 | J32: 0 | K32: =SUM(C32:J32) -> 3
A33: Ndaba | B33: Ncinci | C33: 0 | D33: 0 | E33: 0 | F33: 0 | G33: 0 | H33: 0 | I33: 0 | J33: 0 | K33: =SUM(C33:J33) -> 0
A34: Ndlela | B34: Princess | C34: 0 | D34: 0 | E34: 0 | F34: 1 | G34: 1 | H34: 0 | I34: 0 | J34: 0 | K34: =SUM(C34:J34) -> 2
... A54: Zibonti | B54: Zingisa | C54: 0 | D54: 2 | E54: 1 | F54: 0 | G54: 0 | H54: 0 | I54: 0 | J54: 0 | K54: =SUM(C54:J54) -> 3

Sheet Program Summary Sheet
C1: Week 1 | E1: Week 2 | G1: Week 3 | I1: Week 4 | O1: Week 5 | Q1: Week 6 | S1: Week 7 | U1: Week 8
A2: Last Name | B2: First Name | C2: August 17-20 | D2: Comments | E2: August 24-27 | F2: Comments | G2: August 31-03 | H2: Comments | I2: September 07-10 | J2: Comments | K2: Four Weeks Accumulative Points | L2: Accumulative points | M2: First four weeks % | N2: Comments | O2: September 14-17 | P2: Comments | Q2: September 21-24 | R2: Comments | S2: September 28-01 | T2: Comments | U2: October 05-08 | V2: Accumulative points | W2: End of block | X2: Additional points needed
A3: Masasanya | B3: Thabile | C3: {=INDEX('August 17-20'!AE4:AE18,0)} -> 18 | E3: {=INDEX('August 24-27'!AF4:AF16,0)} -> 17 | G3: {=INDEX('August 31-03'!AE4:AE17,0)} -> 18 | I3: {=INDEX('September 07-10'!AE4:AE10,0)} -> 14 | K3: =58-L3 -> -9 | L3: =sum(C3+E3+G3+I3) -> 67 | M3: =L3/72 -> 0.93055556 | O3: {=INDEX('September 14-17'!AE4:AE16,0)} -> 16 | Q3: {=INDEX('September 21-24'!AE4:AE56,0)} -> 0 | S3: {=INDEX('September 28-01'!AE4:AE56,0)} -> 0 | U3: {=INDEX('October 05-08'!AE4:AE56,0)} -> 0 | V3: =sum(O3+Q3+S3+U3) -> 16 | W3: =V3/66 -> 0.24242424 | X3: =53-V3 -> 37
A4: Buthelezi | B4: Prudence | C4: 16 | E4: 20 | G4: 16 | I4: 14 | K4: =58-L4 -> -8 | L4: =sum(C4+E4+G4+I4) -> 66 | M4: =L4/72 -> 0.91666667 | O4: 14 | Q4: 0 | S4: 0 | U4: 0 | V4: =sum(O4+Q4+S4+U4) -> 14 | W4: =V4/60 -> 0.23333333 | X4: =53-V4 -> 39
A5: Gambushe | B5: Vuyi | C5: 18 | E5: 18 | G5: 18 | I5: 18 | K5: =58-L5 -> -14 | L5: =sum(C5+E5+G5+I5) -> 72 | M5: =L5/72 -> 1 | O5: 12 | Q5: 0 | S5: 0 | U5: 0 | V5: =sum(O5+Q5+S5+U5) -> 12 | W5: =V5/66 -> 0.18181818 | X5: =53-V5 -> 41
A6: Hlatshwayo | B6: Lwazi | C6: 16 | E6: 17.5 | G6: 18 | I6: 13 | K6: =58-L6 -> -6.5 | L6: =sum(C6+E6+G6+I6) -> 64.5 | M6: =L6/72 -> 0.89583333 | O6: 16 | Q6: 0 | S6: 0 | U6: 0 | V6: =sum(O6+Q6+S6+U6) -> 16 | W6: =V6/60 -> 0.26666667 | X6: =48-V6 -> 32
A7: Januarie | B7: Nomathemba | C7: 16 | E7: 18 | G7: 14 | I7: 14 | K7: =58-L7 -> -4 | L7: =sum(C7+E7+G7+I7) -> 62 | M7: =L7/72 -> 0.86111111 | O7: 12 | P7: Email informing student of low credits sent on 17/09/2026 | Q7: 0 | S7: 0 | U7: 0 | V7: =sum(O7+Q7+S7+U7) -> 12 | W7: =V7/66 -> 0.18181818 | X7: =53-V7 -> 41
A8: Kotane | B8: Retshego | C8: 14 | E8: 20 | G8: 16 | I8: 12 | K8: =58-L8 -> -4 | L8: =sum(C8+E8+G8+I8) -> 62 | M8: =L8/72 -> 0.86111111 | O8: 16 | Q8: 0 | S8: 0 | U8: 0 | V8: =sum(O8+Q8+S8+U8) -> 16 | W8: =V8/66 -> 0.24242424 | X8: =53-V8 -> 37
A9: Lebea | B9: Lebohang | C9: 16 | E9: 16 | G9: 16 | I9: 14 | K9: =58-L9 -> -4 | L9: =sum(C9+E9+G9+I9) -> 62 | M9: =L9/72 -> 0.86111111 | O9: 10 | P9: Email informing student of low credits sent on 17/09/2026 | Q9: 0 | S9: 0 | U9: 0 | V9: =sum(O9+Q9+S9+U9) -> 10 | W9: =V9/66 -> 0.15151515 | X9: =53-V9 -> 43
A10: Lekganyane | B10: Molatela | C10: 15 | E10: 17 | G10: 16 | I10: {=INDEX('September 07-10'!AE11:AE15,0)} -> 13.5 | K10: =58-L10 -> -3.5 | L10: =sum(C10+E10+G10+I10) -> 61.5 | M10: =L10/72 -> 0.85416667 | O10: 16 | Q10: 0 | S10: 0 | U10: 0 | V10: =sum(O10+Q10+S10+U10) -> 16 | W10: =V10/60 -> 0.26666667 | X10: =48-V10 -> 32
A11: Lengoati | B11: Phumelela | C11: 16 | E11: 18 | G11: 13.5 | I11: 14 | K11: =58-L11 -> -3.5 | L11: =sum(C11+E11+G11+I11) -> 61.5 | M11: =L11/72 -> 0.85416667 | O11: 14 | Q11: 0 | S11: 0 | U11: 0 | V11: =sum(O11+Q11+S11+U11) -> 14 | W11: =V11/60 -> 0.23333333 | X11: =48-V11 -> 34
A12: Lepyana | B12: Nyaduwa | C12: 15 | E12: 16.5 | G12: 15.5 | I12: 13 | K12: =58-L12 -> -2 | L12: =sum(C12+E12+G12+I12) -> 60 | M12: =L12/72 -> 0.83333333 | O12: 8.5 | P12: Email informing student of low credits sent on 17/09/2026 | Q12: 0 | S12: 0 | U12: 0 | V12: =sum(O12+Q12+S12+U12) -> 8.5 | W12: =V12/66 -> 0.12878788 | X12: =53-V12 -> 44.5
A13: Maake | B13: Lethabo | C13: 16 | E13: 17 | G13: 17 | I13: 12.5 | K13: =58-L13 -> -4.5 | L13: =sum(C13+E13+G13+I13) -> 62.5 | M13: =L13/72 -> 0.86805556 | O13: 7 | P13: Email informing student of low credits sent on 17/09/2026 | Q13: 0 | S13: 0 | U13: 0 | V13: =sum(O13+Q13+S13+U13) -> 7 | W13: =V13/66 -> 0.10606061 | X13: =53-V13 -> 46
A14: Magwasha | B14: Tshimangadzo | C14: 14.5 | E14: 19.5 | G14: 17.5 | I14: 13.5 | K14: =58-L14 -> -7 | L14: =sum(C14+E14+G14+I14) -> 65 | M14: =L14/72 -> 0.90277778 | O14: 14.5 | Q14: 0 | S14: 0 | U14: 0 | V14: =sum(O14+Q14+S14+U14) -> 14.5 | W14: =V14/60 -> 0.24166667 | X14: =48-V14 -> 33.5
A15: Makhabane | B15: Josephina | C15: 9 | D15: Email informing student of low credits sent on 20/08/2026 | E15: 17.5 | G15: 17 | I15: {=INDEX('September 07-10'!AE16,0)} -> 17.5 | K15: =58-L15 -> -3 | L15: =sum(C15+E15+G15+I15) -> 61 | M15: =L15/72 -> 0.84722222 | O15: 8 | P15: Email informing student of low credits sent on 17/09/2026 | Q15: 0 | S15: 0 | U15: 0 | V15: =sum(O15+Q15+S15+U15) -> 8 | W15: =V15/60 -> 0.13333333 | X15: =48-V15 -> 40
A16: Makhafola | B16: Kamogelo | C16: 18 | E16: {=INDEX('August 24-27'!AF17,0)} -> 19 | G16: 18 | I16: {=INDEX('September 07-10'!AE17,0)} -> 11 | K16: =58-L16 -> -8 | L16: =sum(C16+E16+G16+I16) -> 66 | M16: =L16/72 -> 0.91666667 | O16: {=INDEX('September 14-17'!AE17,0)} -> 9.5 | P16: Email informing student of low credits sent on 17/09/2026 | Q16: 0 | S16: 0 | U16: 0 | V16: =sum(O16+Q16+S16+U16) -> 9.5 | W16: =V16/66 -> 0.14393939 | X16: =53-V16 -> 43.5
A17: Mangane | B17: Lebogang | C17: 16 | E17: {=INDEX('August 24-27'!AF20,0)} -> 13 | G17: {=INDEX('August 31-03'!AE20,0)} -> 8 | H17: Email informing student of low credits sent on 03/09/2026 | I17: {=INDEX('September 07-10'!AE20,0)} -> 18 | K17: =58-L17 -> 3 | L17: =sum(C17+E17+G17+I17) -> 55 | M17: =L17/72 -> 0.76388889 | O17: {=INDEX('September 14-17'!AE20,0)} -> 10 | P17: Email informing student of low credits sent on 17/09/2026 | Q17: 0 | S17: 0 | U17: 0 | V17: =sum(O17+Q17+S17+U17) -> 10 | W17: =V17/66 -> 0.15151515 | X17: =53-V17 -> 43
A18: Makhafola | B18: Lerato | C18: {=INDEX('August 17-20'!AE18,0)} -> 16 | E18: {=INDEX('August 24-27'!AF18,0)} -> 17.5 | G18: {=INDEX('August 31-03'!AE18,0)} -> 15.5 | I18: {=INDEX('September 07-10'!AE18,0)} -> 15.5 | K18: =58-L18 -> -6.5 | L18: =sum(C18+E18+G18+I18) -> 64.5 | M18: =L18/72 -> 0.89583333 | O18: {=INDEX('September 14-17'!AE18,0)} -> 16 | Q18: 0 | S18: 0 | U18: 0 | V18: =sum(O18+Q18+S18+U18) -> 16 | W18: =V18/60 -> 0.26666667 | X18: =48-V18 -> 32
A19: Masemola | B19: Gopolang | C19: {=INDEX('August 17-20'!AE19,0)} -> 11 | D19: Email informing student of low credits sent on 20/08/2026 | E19: {=INDEX('August 24-27'!AF19,0)} -> 16.5 | G19: {=INDEX('August 31-03'!AE19,0)} -> 16 | I19: {=INDEX('September 07-10'!AE19,0)} -> 16.5 | K19: =58-L19 -> -2 | L19: =sum(C19+E19+G19+I19) -> 60 | M19: =L19/72 -> 0.83333333 | O19: {=INDEX('September 14-17'!AE19,0)} -> 14 | Q19: 0 | S19: 0 | U19: 0 | V19: =sum(O19+Q19+S19+U19) -> 14 | W19: =V19/60 -> 0.23333333 | X19: =48-V19 -> 34
A20: Mashapa | B20: Morongwa | C20: {=INDEX('August 17-20'!AE21,0)} -> 13.5 | D20: Email informing student of low credits sent on 20/08/2026 | E20: {=INDEX('August 24-27'!AF21,0)} -> 18 | G20: {=INDEX('August 31-03'!AE21,0)} -> 16 | I20: {=INDEX('September 07-10'!AE21:AE56,0)} -> 13.5 | K20: =58-L20 -> -3 | L20: =sum(C20+E20+G20+I20) -> 61 | M20: =L20/72 -> 0.84722222 | O20: {=INDEX('September 14-17'!AE21:AE56,0)} -> 14 | Q20: 0 | S20: 0 | U20: 0 | V20: =sum(O20+Q20+S20+U20) -> 14 | W20: =V20/60 -> 0.23333333 | X20: =48-V20 -> 34
A21: Mbatha | B21: Anele | C21: {=INDEX('August 17-20'!AE22,0)} -> 16 | E21: {=INDEX('August 24-27'!AF22:AF56,0)} -> 17.5 | G21: {=INDEX('August 31-03'!AE22:AE56,0)} -> 15 | I21: 14 | K21: =58-L21 -> -4.5 | L21: =sum(C21+E21+G21+I21) -> 62.5 | M21: =L21/72 -> 0.86805556 | O21: 11.5 | Q21: 0 | S21: 0 | U21: 0 | V21: =sum(O21+Q21+S21+U21) -> 11.5 | W21: =V21/60 -> 0.19166667 | X21: =48-V21 -> 36.5
A22: Mhlongo | B22: Floyd | C22: {=INDEX('August 17-20'!AE23:AE56,0)} -> 18 | E22: 20 | G22: 16 | I22: 16 | K22: =58-L22 -> -12 | L22: =sum(C22+E22+G22+I22) -> 70 | M22: =L22/72 -> 0.97222222 | O22: 12 | P22: Email informing student of low credits sent on 17/09/2026 | Q22: 0 | S22: 0 | U22: 0 | V22: =sum(O22+Q22+S22+U22) -> 12 | W22: =V22/66 -> 0.18181818 | X22: =53-V22 -> 41
A23: Mndwetywa | B23: Yamkelani | C23: 17.5 | E23: 14.5 | G23: 14.5 | I23: 14 | K23: =58-L23 -> -2.5 | L23: =sum(C23+E23+G23+I23) -> 60.5 | M23: =L23/72 -> 0.84027778 | O23: 7 | P23: Email informing student of low credits sent on 17/09/2026 | Q23: 0 | S23: 0 | U23: 0 | V23: =sum(O23+Q23+S23+U23) -> 7 | W23: =V23/66 -> 0.10606061 | X23: =53-V23 -> 46
A24: Moema | B24: Boitshoko | C24: 15.5 | E24: 18 | G24: 18 | I24: 13.5 | K24: =58-L24 -> -7 | L24: =sum(C24+E24+G24+I24) -> 65 | M24: =L24/72 -> 0.90277778 | O24: 12 | Q24: 0 | S24: 0 | U24: 0 | V24: =sum(O24+Q24+S24+U24) -> 12 | W24: =V24/60 -> 0.2 | X24: =48-V24 -> 36
A25: Molaletsa | B25: Karabo | C25: 12 | D25: Email informing student of low credits sent on 20/08/2026 | E25: 18 | G25: 14 | I25: 16 | K25: =58-L25 -> -2 | L25: =sum(C25+E25+G25+I25) -> 60 | M25: =L25/72 -> 0.83333333 | O25: 12 | P25: Email informing student of low credits sent on 17/09/2026 | Q25: 0 | S25: 0 | U25: 0 | V25: =sum(O25+Q25+S25+U25) -> 12 | W25: =V25/66 -> 0.18181818 | X25: =53-V25 -> 41
A26: Monametsi | B26: Refilwe | C26: 14 | E26: 17.5 | G26: 13.5 | H26: Email informing student of low credits sent on 03/09/2026 | I26: 15.5 | K26: =58-L26 -> -2.5 | L26: =sum(C26+E26+G26+I26) -> 60.5 | M26: =L26/72 -> 0.84027778 | O26: 16 | Q26: 0 | S26: 0 | U26: 0 | V26: =sum(O26+Q26+S26+U26) -> 16 | W26: =V26/66 -> 0.24242424 | X26: =53-V26 -> 37
A27: More | B27: Molebatsi | C27: 18 | E27: 14 | F27: Email informing student of low credits sent on 27/08/2026 | G27: 16 | I27: 14 | K27: =58-L27 -> -4 | L27: =sum(C27+E27+G27+I27) -> 62 | M27: =L27/72 -> 0.86111111 | O27: 14 | Q27: 0 | S27: 0 | U27: 0 | V27: =sum(O27+Q27+S27+U27) -> 14 | W27: =V27/66 -> 0.21212121 | X27: =53-V27 -> 39
A28: Motimele | B28: Tshegofatso | C28: 12 | D28: Email informing student of low credits sent on 20/08/2026 | E28: 18 | G28: 14 | I28: 14 | K28: =58-L28 -> 0 | L28: =sum(C28+E28+G28+I28) -> 58 | M28: =L28/72 -> 0.80555556 | O28: 8 | P28: Email informing student of low credits sent on 17/09/2026 | Q28: 0 | S28: 0 | U28: 0 | V28: =sum(O28+Q28+S28+U28) -> 8 | W28: =V28/66 -> 0.12121212 | X28: =53-V28 -> 45
A29: Mthethwa | B29: Sanele | C29: 14.5 | E29: 13.5 | F29: Email informing student of low credits sent on 27/08/2026 | G29: 17.5 | I29: 15 | K29: =58-L29 -> -2.5 | L29: =sum(C29+E29+G29+I29) -> 60.5 | M29: =L29/72 -> 0.84027778 | O29: 13.5 | Q29: 0 | S29: 0 | U29: 0 | V29: =sum(O29+Q29+S29+U29) -> 13.5 | W29: =V29/60 -> 0.225 | X29: =48-V29 -> 34.5
A30: Mtshakazi | B30: Vuyolwethu | C30: 16 | E30: 16 | G30: 16 | I30: 14 | K30: =58-L30 -> -4 | L30: =sum(C30+E30+G30+I30) -> 62 | M30: =L30/72 -> 0.86111111 | O30: 16 | Q30: 0 | S30: 0 | U30: 0 | V30: =sum(O30+Q30+S30+U30) -> 16 | W30: =V30/60 -> 0.26666667 | X30: =48-V30 -> 32
A31: Nawa | B31: Ontlametse | C31: 16 | E31: 18 | G31: 16 | I31: 16 | K31: =58-L31 -> -8 | L31: =sum(C31+E31+G31+I31) -> 66 | M31: =L31/72 -> 0.91666667 | O31: 16 | Q31: 0 | S31: 0 | U31: 0 | V31: =sum(O31+Q31+S31+U31) -> 16 | W31: =V31/66 -> 0.24242424 | X31: =53-V31 -> 37
A32: Ncube | B32: Thembisile | C32: 15.5 | E32: 14 | F32: Email informing student of low credits sent on 27/08/2026 | G32: 16 | I32: 15 | K32: =58-L32 -> -2.5 | L32: =sum(C32+E32+G32+I32) -> 60.5 | M32: =L32/72 -> 0.84027778 | O32: 11 | Q32: 0 | S32: 0 | U32: 0 | V32: =sum(O32+Q32+S32+U32) -> 11 | W32: =V32/66 -> 0.16666667 | X32: =53-V32 -> 42
A33: Ndaba | B33: Aobakwe | C33: 18 | E33: 18 | G33: 18 | I33: 12 | K33: =58-L33 -> -8 | L33: =sum(C33+E33+G33+I33) -> 66 | M33: =L33/72 -> 0.91666667 | O33: 12 | Q33: 0 | S33: 0 | U33: 0 | V33: =sum(O33+Q33+S33+U33) -> 12 | W33: =V33/66 -> 0.18181818 | X33: =53-V33 -> 41
A34: Ndaba | B34: Ncinci | C34: 18 | E34: 18 | G34: 18 | I34: 18 | K34: =58-L34 -> -14 | L34: =sum(C34+E34+G34+I34) -> 72 | M34: =L34/72 -> 1 | O34: 16 | Q34: 0 | S34: 0 | U34: 0 | V34: =sum(O34+Q34+S34+U34) -> 16 | W34: =V34/66 -> 0.24242424 | X34: =53-V34 -> 37
A35: Ndlela | B35: Princess | C35: 16 | E35: 18 | G35: 14 | I35: 12 | K35: =58-L35 -> -2 | L35: =sum(C35+E35+G35+I35) -> 60 | M35: =L35/72 -> 0.83333333 | O35: 12 | P35: Email informing student of low credits sent on 17/09/2026 | Q35: 0 | S35: 0 | U35: 0 | V35: =sum(O35+Q35+S35+U35) -> 12 | W35: =V35/66 -> 0.18181818 | X35: =53-V35 -> 41
A36: Ndou | B36: Sedzani | C36: 17 | E36: 16 | G36: 14 | I36: 13 | K36: =58-L36 -> -2 | L36: =sum(C36+E36+G36+I36) -> 60 | M36: =L36/72 -> 0.83333333 | O36: 3.5 | Q36: 0 | S36: 0 | U36: 0 | V36: =sum(O36+Q36+S36+U36) -> 3.5 | W36: =V36/66 -> 0.053030303 | X36: =53-V36 -> 49.5
A37: Ngcobo | B37: Hlengiwe | C37: 18 | E37: 17.5 | G37: 16 | I37: 10 | J37: Email informing student of low credits sent on 14/09/2026 | K37: =58-L37 -> -3.5 | L37: =sum(C37+E37+G37+I37) -> 61.5 | M37: =L37/72 -> 0.85416667 | O37: 16 | Q37: 0 | S37: 0 | U37: 0 | V37: =sum(O37+Q37+S37+U37) -> 16 | W37: =V37/66 -> 0.24242424 | X37: =53-V37 -> 37
A38: Nhlabathi | B38: Kuku | C38: 13.5 | E38: 18 | G38: 15.5 | I38: 13.5 | K38: =58-L38 -> -2.5 | L38: =sum(C38+E38+G38+I38) -> 60.5 | M38: =L38/72 -> 0.84027778 | O38: 13.5 | Q38: 0 | S38: 0 | U38: 0 | V38: =sum(O38+Q38+S38+U38) -> 13.5 | W38: =V38/60 -> 0.225 | X38: =48-V38 -> 34.5
A39: Nkawule | B39: Unathi | C39: 16 | E39: 17.5 | G39: 15.5 | I39: 12 | K39: =58-L39 -> -3 | L39: =sum(C39+E39+G39+I39) -> 61 | M39: =L39/72 -> 0.84722222 | O39: 12 | P39: Email informing student of low credits sent on 17/09/2026 | Q39: 0 | S39: 0 | U39: 0 | V39: =sum(O39+Q39+S39+U39) -> 12 | W39: =V39/60 -> 0.2 | X39: =48-V39 -> 36
A40: Nkosi | B40: Thobeka | C40: 18 | E40: 18 | G40: 16 | I40: 16 | K40: =58-L40 -> -10 | L40: =sum(C40+E40+G40+I40) -> 68 | M40: =L40/72 -> 0.94444444 | O40: 12 | Q40: 0 | S40: 0 | U40: 0 | V40: =sum(O40+Q40+S40+U40) -> 12 | W40: =V40/66 -> 0.18181818 | X40: =53-V40 -> 41
...

Sheet August 17-20
F1: MGT-378 Marketing Management
F2: Student attended class | G2: In class OR Online only | I2: Program Attendance | K2: Student attended class | L2: In class OR Online only | N2: Program Attendance | P2: Student attended class | Q2: In class OR Online only | S2: Program Attendance | U2: Student attended class | V2: In class OR Online only | X2: Program Attendance | Z2: Friday Program | AB2: Saturday
A3: NR | B3: Group | C3: Location | D3: Last Name | E3: First Name | F3: MONDAY | G3: Online/In Class | H3: Student Behavior in Class Comments | I3: Morning | J3: Afternoon | K3: TUESDAY | L3: Online/In Class | M3: Student Behavior in Class Comments | N3: Morning | O3: Afternoon | P3: WEDNESDAY | Q3: Online/In Class | R3: Student Behavior in Class Comments | S3: Morning | T3: Afternoon | U3: THURSDAY | V3: Online/In Class | W3: Student Behavior in Class Comments | X3: Morning | Y3: Afternoon | Z3: Morning | AA3: PM- Extra | AB3: AM-Extra | AC3: PM- Extra | AD3: Total absence this week | AE3: Total Program Attendance this week | AF3: Oustanding Credits
A4: 1 | B4: N | D4: Masasanya | E4: Thabile | F4: Yes | G4: In class | I4: 2 | J4: 2 | K4: Yes | L4: In class | N4: 2 | O4: 2 | P4: Yes | Q4: In class | S4: 2 | T4: 2 | U4: Yes | V4: In class | X4: 2 | Y4: 2 | Z4: 2 | AA4: 0 | AB4: 0 | AC4: 0 | AD4: 0 | AE4: =I4+J4+N4+O4+S4+T4+X4+Y4+Z4+AA4+AB4+AC4 -> 18 | AF4: =14.5-AE4 -> -3.5
A5: 2 | B5: S | D5: Buthelezi | E5: Prudence | F5: Yes | G5: In class | I5: 2 | J5: 2 | K5: Yes | L5: In class | N5: 2 | O5: 2 | P5: Yes | Q5: In class | S5: 2 | T5: 2 | U5: Yes | V5: In class | X5: 2 | Y5: 2 | Z5: 0 | AA5: 0 | AB5: 0 | AC5: 0 | AD5: 0 | AE5: =I5+J5+N5+O5+S5+T5+X5+Y5+Z5+AA5+AB5+AC5 -> 16 | AF5: =14.5-AE5 -> -1.5
A6: 3 | B6: S | C6: D | D6: Gambushe | E6: Vuyi | F6: Yes | G6: In class | I6: 2 | J6: 2 | K6: Yes | L6: In class | N6: 2 | O6: 2 | P6: Yes | Q6: In class | S6: 2 | T6: 2 | U6: Yes | V6: In class | X6: 2 | Y6: 2 | Z6: 2 | AA6: 0 | AB6: 0 | AC6: 0 | AD6: 0 | AE6: =I6+J6+N6+O6+S6+T6+X6+Y6+Z6+AA6+AB6+AC6 -> 18 | AF6: =14.5-AE6 -> -3.5
A7: 4 | B7: S | D7: Hlatshwayo | E7: Lwazi | F7: Yes | G7: In class | I7: 2 | J7: 2 | K7: Yes | L7: In class | M7: Busy on her phone | N7: 2 | O7: 2 | P7: Yes | Q7: In class | S7: 2 | T7: 2 | U7: Yes | V7: In class | X7: 2 | Y7: 2 | Z7: 0 | AA7: 0 | AB7: 0 | AC7: 0 | AD7: 0 | AE7: =I7+J7+N7+O7+S7+T7+X7+Y7+Z7+AA7+AB7+AC7 -> 16 | AF7: =14.5-AE7 -> -1.5
A8: 5 | B8: S | D8: Januarie | E8: Nomathemba | F8: Yes | G8: In class | I8: 2 | J8: 2 | K8: Yes | L8: In class | N8: 2 | O8: 2 | P8: Yes | Q8: In class | S8: 2 | T8: 2 | U8: Yes | V8: In class | X8: 2 | Y8: 2 | Z8: 0 | AA8: 0 | AB8: 0 | AC8: 0 | AD8: 0 | AE8: =I8+J8+N8+O8+S8+T8+X8+Y8+Z8+AA8+AB8+AC8 -> 16 | AF8: =14.5-AE8 -> -1.5
A9: 6 | B9: S | D9: Kotane | E9: Retshego | F9: Yes | G9: In class | I9: 0 | J9: 2 | K9: Yes | L9: In class | N9: 2 | O9: 2 | P9: Yes | Q9: In class | S9: 2 | T9: 2 | U9: Yes | V9: In class | X9: 2 | Y9: 2 | Z9: 0 | AA9: 0 | AB9: 0 | AC9: 0 | AD9: 0 | AE9: =I9+J9+N9+O9+S9+T9+X9+Y9+Z9+AA9+AB9+AC9 -> 14 | AF9: =14.5-AE9 -> 0.5
A10: 7 | B10: S | D10: Lebea | E10: Lebohang | F10: Yes | G10: In class | H10: Not paying attention in class | I10: 2 | J10: 2 | K10: Yes | L10: In class | M10: Left class at 17:10, did not say anything to us. | N10: 2 | O10: 2 | P10: Yes | Q10: In class | S10: 2 | T10: 2 | U10: Yes | V10: In class | W10: Logged in at 16:16. Left class at 16:50 | X10: 2 | Y10: 2 | Z10: 0 | AA10: 0 | AB10: 0 | AC10: 0 | AD10: 0 | AE10: =I10+J10+N10+O10+S10+T10+X10+Y10+Z10+AA10+AB10+AC10 -> 16 | AF10: =14.5-AE10 -> -1.5
A11: 8 | B11: S | D11: Lekganyane | E11: Molatela | F11: Yes | G11: In class | I11: 2 | J11: 1.5 | K11: Yes | L11: In class | N11: 2 | O11: 2 | P11: Yes | Q11: In class | S11: 2 | T11: 1.5 | U11: Yes | V11: In class | X11: 2 | Y11: 2 | Z11: 0 | AA11: 0 | AB11: 0 | AC11: 0 | AD11: 0 | AE11: =I11+J11+N11+O11+S11+T11+X11+Y11+Z11+AA11+AB11+AC11 -> 15 | AF11: =14.5-AE11 -> -0.5
A12: 9 | B12: S | D12: Lengoati | E12: Phumelela | F12: Yes | G12: In class | I12: 2 | J12: 2 | K12: Yes | L12: In class | N12: 2 | O12: 2 | P12: Yes | Q12: In class | S12: 2 | T12: 2 | U12: Yes | V12: In class | X12: 2 | Y12: 2 | Z12: 0 | AA12: 0 | AB12: 0 | AC12: 0 | AD12: 0 | AE12: =I12+J12+N12+O12+S12+T12+X12+Y12+Z12+AA12+AB12+AC12 -> 16 | AF12: =14.5-AE12 -> -1.5
A13: 10 | B13: S | D13: Lepyana | E13: Nyaduwa | F13: Yes | G13: In class | I13: 2 | J13: 2 | K13: Yes | L13: In class | N13: 2 | O13: 2 | P13: Yes | Q13: In class | S13: 1 | T13: 2 | U13: Yes | V13: In class | X13: 2 | Y13: 2 | Z13: 0 | AA13: 0 | AB13: 0 | AC13: 0 | AD13: 0 | AE13: =I13+J13+N13+O13+S13+T13+X13+Y13+Z13+AA13+AB13+AC13 -> 15 | AF13: =14.5-AE13 -> -0.5
A14: 11 | B14: S | D14: Maake | E14: Lethabo | F14: Yes | G14: In class | I14: 2 | J14: 1.5 | K14: Yes | L14: In class | N14: 1 | O14: 2 | P14: Yes | Q14: In class | S14: 1.5 | T14: 2 | U14: Yes | V14: In class | X14: 2 | Y14: 2 | Z14: 2 | AA14: 0 | AB14: 0 | AC14: 0 | AD14: 0 | AE14: =I14+J14+N14+O14+S14+T14+X14+Y14+Z14+AA14+AB14+AC14 -> 16 | AF14: =14.5-AE14 -> -1.5
A15: 12 | B15: S | D15: Magwasha | E15: Tshimangadzo | F15: Yes | G15: In class | I15: 0 | J15: 2 | K15: Yes | L15: In class | N15: 2 | O15: 2 | P15: Yes | Q15: In class | S15: 2 | T15: 1.5 | U15: Yes | V15: In class | X15: 1.5 | Y15: 2 | Z15: 1.5 | AA15: 0 | AB15: 0 | AC15: 0 | AD15: 0 | AE15: =I15+J15+N15+O15+S15+T15+X15+Y15+Z15+AA15+AB15+AC15 -> 14.5 | AF15: =14.5-AE15 -> 0
A16: 13 | B16: S | D16: Makhabane | E16: Josephina | F16: Yes | G16: In class | H16: Busy on her phone | I16: 0 | J16: 0 | K16: No | L16: Absent | N16: 0 | O16: 0 | P16: Yes | Q16: In class | S16: 2 | T16: 2 | U16: Yes | V16: In class | X16: 1.5 | Y16: 1.5 | Z16: 2 | AA16: 0 | AB16: 0 | AC16: 0 | AD16: 1 | AE16: =I16+J16+N16+O16+S16+T16+X16+Y16+Z16+AA16+AB16+AC16 -> 9 | AF16: =14.5-AE16 -> 5.5
A17: 14 | B17: S | D17: Makhafola | E17: Kamogelo | F17: Yes | G17: In class | I17: 2 | J17: 2 | K17: Yes | L17: In class | N17: 2 | O17: 2 | P17: Yes | Q17: In class | S17: 2 | T17: 2 | U17: Yes | V17: In class | X17: 2 | Y17: 2 | Z17: 2 | AA17: 0 | AB17: 0 | AC17: 0 | AD17: 0 | AE17: =I17+J17+N17+O17+S17+T17+X17+Y17+Z17+AA17+AB17+AC17 -> 18 | AF17: =14.5-AE17 -> -3.5
A18: 15 | B18: S | D18: Makhafola | E18: Lerato | F18: Yes | G18: In class | I18: 2 | J18: 2 | K18: Yes | L18: In class | N18: 2 | O18: 2 | P18: Yes | Q18: In class | S18: 2 | T18: 2 | U18: Yes | V18: In class | X18: 2 | Y18: 2 | Z18: 0 | AA18: 0 | AB18: 0 | AC18: 0 | AD18: 0 | AE18: =I18+J18+N18+O18+S18+T18+X18+Y18+Z18+AA18+AB18+AC18 -> 16 | AF18: =14.5-AE18 -> -1.5
A19: 16 | B19: S | D19: Masemola | E19: Gopolang | F19: Yes | G19: In class | I19: 0 | J19: 0 | K19: Yes | L19: In class | N19: 0 | O19: 2 | P19: Yes | Q19: In class | S19: 2 | T19: 2 | U19: Yes | V19: In class | X19: 1.5 | Y19: 2 | Z19: 1.5 | AA19: 0 | AB19: 0 | AC19: 0 | AD19: 0 | AE19: =I19+J19+N19+O19+S19+T19+X19+Y19+Z19+AA19+AB19+AC19 -> 11 | AF19: =14.5-AE19 -> 3.5
A20: 17 | B20: S | D20: Mangane | E20: Lebogang | F20: Yes | G20: In class | I20: 0 | J20: 1 | K20: Yes | L20: In class | N20: 1 | O20: 2 | P20: Yes | Q20: In class | S20: 1 | T20: 1 | U20: No | V20: Absent | X20: 0 | Y20: 0 | Z20: 1 | AA20: 0 | AB20: 0 | AC20: 0 | AD20: 1 | AE20: =I20+J20+N20+O20+S20+T20+X20+Y20+Z20+AA20+AB20+AC20 -> 7 | AF20: =14.5-AE20 -> 7.5
A21: 18 | B21: S | D21: Mashapa | E21: Morongwa | F21: Yes | G21: In class | I21: 0 | J21: 2 | K21: Yes | L21: In class | N21: 2 | O21: 2 | P21: Yes | Q21: In class | S21: 1.5 | T21: 2 | U21: Yes | V21: In class | X21: 0 | Y21: 2 | Z21: 2 | AA21: 0 | AB21: 0 | AC21: 0 | AD21: 0 | AE21: =I21+J21+N21+O21+S21+T21+X21+Y21+Z21+AA21+AB21+AC21 -> 13.5 | AF21: =14.5-AE21 -> 1
A22: 19 | B22: S | D22: Mbatha | E22: Anele | F22: Yes | G22: In class | I22: 2 | J22: 2 | K22: Yes | L22: In class | N22: 2 | O22: 2 | P22: Yes | Q22: In class | S22: 2 | T22: 2 | U22: Yes | V22: In class | X22: 2 | Y22: 2 | Z22: 0 | AA22: 0 | AB22: 0 | AC22: 0 | AD22: 0 | AE22: =I22+J22+N22+O22+S22+T22+X22+Y22+Z22+AA22+AB22+AC22 -> 16 | AF22: =14.5-AE22 -> -1.5
A23: 20 | B23: S | D23: Mhlongo | E23: Floyd | F23: Yes | G23: In class | I23: 2 | J23: 2 | K23: Yes | L23: In class | N23: 2 | O23: 2 | P23: Yes | Q23: In class | S23: 2 | T23: 2 | U23: Yes | V23: In class | X23: 2 | Y23: 2 | Z23: 2 | AA23: 0 | AB23: 0 | AC23: 0 | AD23: 0 | AE23: =I23+J23+N23+O23+S23+T23+X23+Y23+Z23+AA23+AB23+AC23 -> 18 | AF23: =14.5-AE23 -> -3.5
A24: 21 | B24: S | D24: Mndwetywa | E24: Yamkelani | F24: No | G24: Absent | H24: The camera is off and she has been notified, she only switched it on after being notified at 16:38 | I24: 2 | J24: 2 | K24: Yes | L24: In class | N24: 1.5 | O24: 2 | P24: Yes | Q24: In class | S24: 2 | T24: 2 | U24: Yes | V24: In class | X24: 2 | Y24: 2 | Z24: 2 | AA24: 0 | AB24: 0 | AC24: 0 | AD24: 1 | AE24: =I24+J24+N24+O24+S24+T24+X24+Y24+Z24+AA24+AB24+AC24 -> 17.5 | AF24: =14.5-AE24 -> -3
A25: 22 | B25: S | D25: Moema | E25: Boitshoko | F25: Yes | G25: In class | I25: 2 | J25: 2 | K25: Yes | L25: In class | N25: 2 | O25: 2 | P25: Yes | Q25: In class | S25: 2 | T25: 1.5 | U25: Yes | V25: In class | X25: 2 | Y25: 2 | Z25: 0 | AA25: 0 | AB25: 0 | AC25: 0 | AD25: 0 | AE25: =I25+J25+N25+O25+S25+T25+X25+Y25+Z25+AA25+AB25+AC25 -> 15.5 | AF25: =14.5-AE25 -> -1
A26: 23 | B26: S | D26: Molaletsa | E26: Karabo | F26: Yes | G26: In class | I26: 2 | J26: 2 | K26: No | L26: Absent | N26: 0 | O26: 0 | P26: Yes | Q26: In class | S26: 2 | T26: 2 | U26: Yes | V26: In class | X26: 2 | Y26: 2 | Z26: 0 | AA26: 0 | AB26: 0 | AC26: 0 | AD26: 1 | AE26: =I26+J26+N26+O26+S26+T26+X26+Y26+Z26+AA26+AB26+AC26 -> 12 | AF26: =14.5-AE26 -> 2.5
A27: 24 | B27: S | D27: Monametsi | E27: Refilwe | F27: Yes | G27: In class | I27: 1 | J27: 1.5 | K27: Yes | L27: In class | N27: 0.5 | O27: 2 | P27: Yes | Q27: In class | S27: 2 | T27: 2 | U27: Yes | V27: In class | X27: 2 | Y27: 2 | Z27: 1 | AA27: 0 | AB27: 0 | AC27: 0 | AD27: 0 | AE27: =I27+J27+N27+O27+S27+T27+X27+Y27+Z27+AA27+AB27+AC27 -> 14 | AF27: =14.5-AE27 -> 0.5
A28: 25 | B28: S | D28: More | E28: Molebatsi | F28: Yes | G28: In class | I28: 2 | J28: 2 | K28: Yes | L28: In class | N28: 2 | O28: 2 | P28: Yes | Q28: In class | S28: 2 | T28: 2 | U28: Yes | V28: In class | X28: 2 | Y28: 2 | Z28: 2 | AA28: 0 | AB28: 0 | AC28: 0 | AD28: 0 | AE28: =I28+J28+N28+O28+S28+T28+X28+Y28+Z28+AA28+AB28+AC28 -> 18 | AF28: =14.5-AE28 -> -3.5
A29: 26 | B29: S | D29: Motimele | E29: Tshegofatso | F29: Yes | G29: In class | H29: Not paying attention in class | I29: 2 | J29: 2 | K29: No | L29: Absent | N29: 0 | O29: 0 | P29: Yes | Q29: In class | S29: 2 | T29: 2 | U29: Yes | V29: In class | X29: 2 | Y29: 2 | Z29: 0 | AA29: 0 | AB29: 0 | AC29: 0 | AD29: 1 | AE29: =I29+J29+N29+O29+S29+T29+X29+Y29+Z29+AA29+AB29+AC29 -> 12 | AF29: =14.5-AE29 -> 2.5
A30: 27 | B30: S | D30: Mthethwa | E30: Sanele | F30: Yes | G30: In class | I30: 0 | J30: 2 | K30: Yes | L30: In class | N30: 2 | O30: 2 | P30: Yes | Q30: In class | S30: 1.5 | T30: 2 | U30: Yes | V30: In class | X30: 1.5 | Y30: 2 | Z30: 1.5 | AA30: 0 | AB30: 0 | AC30: 0 | AD30: 0 | AE30: =I30+J30+N30+O30+S30+T30+X30+Y30+Z30+AA30+AB30+AC30 -> 14.5 | AF30: =14.5-AE30 -> 0
A31: 28 | B31: S | D31: Mtshakazi | E31: Vuyolwethu | F31: Yes | G31: In class | I31: 2 | J31: 2 | K31: Yes | L31: In class | N31: 2 | O31: 2 | P31: Yes | Q31: In class | S31: 2 | T31: 2 | U31: Yes | V31: In class | X31: 2 | Y31: 2 | Z31: 0 | AA31: 0 | AB31: 0 | AC31: 0 | AD31: 2 | AE31: =I31+J31+N31+O31+S31+T31+X31+Y31+Z31+AA31+AB31+AC31 -> 16 | AF31: =14.5-AE31 -> -1.5
A32: 29 | B32: S | D32: Nawa | E32: Ontlametse | F32: Yes | G32: In class | I32: 0 | J32: 2 | K32: Yes | L32: In class | N32: 2 | O32: 2 | P32: Yes | Q32: In class | S32: 2 | T32: 2 | U32: Yes | V32: In class | X32: 2 | Y32: 2 | Z32: 2 | AA32: 0 | AB32: 0 | AC32: 0 | AD32: 0 | AE32: =I32+J32+N32+O32+S32+T32+X32+Y32+Z32+AA32+AB32+AC32 -> 16 | AF32: =14.5-AE32 -> -1.5
A33: 30 | B33: S | D33: Ncube | E33: Thembisile | F33: No | G33: Absent | I33: 2 | J33: 0 | K33: Yes | L33: In class | N33: 2 | O33: 2 | P33: Yes | Q33: In class | S33: 1.5 | T33: 2 | U33: Yes | V33: In class | X33: 2 | Y33: 2 | Z33: 2 | AA33: 0 | AB33: 0 | AC33: 0 | AD33: 1 | AE33: =I33+J33+N33+O33+S33+T33+X33+Y33+Z33+AA33+AB33+AC33 -> 15.5 | AF33: =14.5-AE33 -> -1
A34: 31 | B34: S | D34: Ndaba | E34: Aobakwe | F34: Yes | G34: In class | I34: 2 | J34: 2 | K34: Yes | L34: In class | N34: 2 | O34: 2 | P34: Yes | Q34: In class | S34: 2 | T34: 2 | U34: Yes | V34: In class | X34: 2 | Y34: 2 | Z34: 2 | AA34: 0 | AB34: 0 | AC34: 0 | AD34: 0 | AE34: =I34+J34+N34+O34+S34+T34+X34+Y34+Z34+AA34+AB34+AC34 -> 18 | AF34: =14.5-AE34 -> -3.5
A35: 32 | B35: S | C35: D | D35: Ndaba | E35: Ncinci | F35: Yes | G35: In class | I35: 2 | J35: 2 | K35: Yes | L35: In class | N35: 2 | O35: 2 | P35: Yes | Q35: In class | S35: 2 | T35: 2 | U35: Yes | V35: In class | X35: 2 | Y35: 2 | Z35: 2 | AA35: 0 | AB35: 0 | AC35: 0 | AD35: 0 | AE35: =I35+J35+N35+O35+S35+T35+X35+Y35+Z35+AA35+AB35+AC35 -> 18 | AF35: =14.5-AE35 -> -3.5
A36: 33 | B36: S | D36: Ndlela | E36: Princess | F36: Yes | G36: In class | I36: 2 | J36: 2 | K36: Yes | L36: In class | N36: 2 | O36: 2 | P36: Yes | Q36: In class | S36: 2 | T36: 2 | U36: Yes | V36: In class | X36: 2 | Y36: 2 | Z36: 0 | AA36: 0 | AB36: 0 | AC36: 0 | AD36: 0 | AE36: =I36+J36+N36+O36+S36+T36+X36+Y36+Z36+AA36+AB36+AC36 -> 16 | AF36: =14.5-AE36 -> -1.5
A37: 34 | B37: S | D37: Ndou | E37: Sedzani | F37: Yes | G37: In class | I37: 2 | J37: 1 | K37: Yes | L37: In class | N37: 2 | O37: 1 | P37: Yes | Q37: In class | S37: 2 | T37: 1 | U37: Yes | V37: In class | X37: 2 | Y37: 1 | Z37: 2 | AA37: 1 | AB37: 2 | AC37: 0 | AD37: 0 | AE37: =I37+J37+N37+O37+S37+T37+X37+Y37+Z37+AA37+AB37+AC37 -> 17 | AF37: =14.5-AE37 -> -2.5
A38: 35 | B38: S | C38: D | D38: Ngcobo | E38: Hlengiwe | F38: Yes | G38: In class | I38: 2 | J38: 2 | K38: Yes | L38: In class | N38: 2 | O38: 2 | P38: Yes | Q38: In class | S38: 2 | T38: 2 | U38: Yes | V38: In class | X38: 2 | Y38: 2 | Z38: 2 | AA38: 0 | AB38: 0 | AC38: 0 | AD38: 0 | AE38: =I38+J38+N38+O38+S38+T38+X38+Y38+Z38+AA38+AB38+AC38 -> 18 | AF38: =14.5-AE38 -> -3.5
A39: 36 | B39: S | D39: Nhlabathi | E39: Kuku | F39: Yes | G39: In class | I39: 0 | J39: 1.5 | K39: Yes | L39: In class | N39: 2 | O39: 2 | P39: Yes | Q39: In class | S39: 2 | T39: 2 | U39: Yes | V39: In class | X39: 2 | Y39: 2 | Z39: 0 | AA39: 0 | AB39: 0 | AC39: 0 | AD39: 0 | AE39: =I39+J39+N39+O39+S39+T39+X39+Y39+Z39+AA39+AB39+AC39 -> 13.5 | AF39: =14.5-AE39 -> 1
A40: 37 | B40: S | D40: Nkawule | E40: Unathi | F40: Yes | G40: In class | I40: 2 | J40: 2 | K40: Yes | L40: In class | N40: 2 | O40: 2 | P40: Yes | Q40: In class | S40: 2 | T40: 2 | U40: Yes | V40: In class | X40: 2 | Y40: 2 | Z40: 0 | AA40: 0 | AB40: 0 | AC40: 0 | AD40: 0 | AE40: =I40+J40+N40+O40+S40+T40+X40+Y40+Z40+AA40+AB40+AC40 -> 16 | AF40: =14.5-AE40 -> -1.5
...

Sheet August 24-27
F1: MGT-378 Marketing Management
F2: Student attended class | G2: In class OR Online only | I2: Program Attendance | K2: Student attended class | L2: In class OR Online only | N2: Program Attendance | P2: Student attended class | Q2: In class OR Online only | S2: Program Attendance | V2: Student attended class | W2: In class OR Online only | Y2: Program Attendance | AA2: Friday Program | AC2: Saturday
A3: NR | B3: Group | C3: Location | D3: Last Name | E3: First Name | F3: MONDAY | G3: Online/In Class | H3: Student Behavior in Class Comments | I3: Morning | J3: Afternoon | K3: TUESDAY | L3: Online/In Class | M3: Student Behavior in Class Comments | N3: Morning | O3: Afternoon | P3: WEDNESDAY | Q3: Online/In Class | R3: Student Behavior in Class Comments | S3: Morning | T3: 2nd- Morning | U3: Afternoon | V3: THURSDAY | W3: Online/In Class | X3: Student Behavior in Class Comments | Y3: Morning | Z3: Afternoon | AA3: Morning | AB3: PM- Extra | AC3: AM-Extra | AD3: PM- Extra | AE3: Total absence this week | AF3: Total Program Attendance this week | AG3: Oustanding Credits | AH3: Oustanding Credits
A4: 1 | B4: N | D4: Masasanya | E4: Thabile | F4: Yes | G4: In class | I4: 2 | J4: 2 | K4: Yes | L4: In class | N4: 2 | O4: 2 | P4: Yes | Q4: In class | S4: 1 | T4: 2 | U4: 2 | V4: Yes | W4: In class | Y4: 2 | Z4: 2 | AA4: 0 | AB4: 0 | AC4: 0 | AD4: 0 | AE4: 0 | AF4: =I4+J4+N4+O4+S4+T4+U4+Y4+Z4+AA4+AB4+AC4+AD4 -> 17 | AG4: =14.5-AF4 -> -2.5 | AH4: =14.5-AG4 -> 17
A5: 2 | B5: S | D5: Buthelezi | E5: Prudence | F5: Yes | G5: In class | I5: 2 | J5: 2 | K5: Yes | L5: In class | N5: 2 | O5: 2 | P5: Yes | Q5: In class | S5: 2 | T5: 2 | U5: 2 | V5: Yes | W5: In class | Y5: 2 | Z5: 2 | AA5: 2 | AB5: 0 | AC5: 0 | AD5: 0 | AE5: 0 | AF5: =I5+J5+N5+O5+S5+T5+U5+Y5+Z5+AA5+AB5+AC5+AD5 -> 20 | AG5: =14.5-AF5 -> -5.5 | AH5: =14.5-AG5 -> 20
A6: 3 | B6: S | C6: D | D6: Gambushe | E6: Vuyi | F6: Yes | G6: In class | I6: 2 | J6: 2 | K6: Yes | L6: In class | N6: 2 | O6: 2 | P6: Yes | Q6: In class | S6: 2 | T6: 0 | U6: 2 | V6: Yes | W6: In class | Y6: 2 | Z6: 2 | AA6: 2 | AB6: 0 | AC6: 0 | AD6: 0 | AE6: 0 | AF6: =I6+J6+N6+O6+S6+T6+U6+Y6+Z6+AA6+AB6+AC6+AD6 -> 18 | AG6: =14.5-AF6 -> -3.5 | AH6: =14.5-AG6 -> 18
A7: 4 | B7: S | D7: Hlatshwayo | E7: Lwazi | F7: Yes | G7: In class | I7: 2 | J7: 2 | K7: Yes | L7: In class | M7: Busy on her phone | N7: 1.5 | O7: 2 | P7: Yes | Q7: In class | S7: 2 | T7: 2 | U7: 2 | V7: Yes | W7: In class | X7: Took extra 20 minute for break. | Y7: 2 | Z7: 2 | AA7: 0 | AB7: 0 | AC7: 0 | AD7: 0 | AE7: 0 | AF7: =I7+J7+N7+O7+S7+T7+U7+Y7+Z7+AA7+AB7+AC7+AD7 -> 17.5 | AG7: =14.5-AF7 -> -3 | AH7: =14.5-AG7 -> 17.5
A8: 5 | B8: S | D8: Januarie | E8: Nomathemba | F8: Yes | G8: In class | I8: 2 | J8: 2 | K8: Yes | L8: In class | M8: Busy on her phone | N8: 2 | O8: 2 | P8: Yes | Q8: In class | S8: 2 | T8: 2 | U8: 2 | V8: Yes | W8: In class | Y8: 2 | Z8: 2 | AA8: 0 | AB8: 0 | AC8: 0 | AD8: 0 | AE8: 0 | AF8: =I8+J8+N8+O8+S8+T8+U8+Y8+Z8+AA8+AB8+AC8+AD8 -> 18 | AG8: =14.5-AF8 -> -3.5 | AH8: =14.5-AG8 -> 18
A9: 6 | B9: S | D9: Kotane | E9: Retshego | F9: Yes | G9: In class | I9: 2 | J9: 2 | K9: Yes | L9: In class | N9: 2 | O9: 2 | P9: Yes | Q9: In class | S9: 2 | T9: 2 | U9: 2 | V9: No | W9: Absent | Y9: 2 | Z9: 2 | AA9: 2 | AB9: 0 | AC9: 0 | AD9: 0 | AE9: 1 | AF9: =I9+J9+N9+O9+S9+T9+U9+Y9+Z9+AA9+AB9+AC9+AD9 -> 20 | AG9: =14.5-AF9 -> -5.5 | AH9: =14.5-AG9 -> 20
A10: 7 | B10: S | D10: Lebea | E10: Lebohang | F10: Yes | G10: In class | I10: 2 | J10: 2 | K10: Yes | L10: In class | N10: 2 | O10: 2 | P10: Yes | Q10: In class | S10: 2 | T10: 0 | U10: 2 | V10: Yes | W10: In class | Y10: 2 | Z10: 2 | AA10: 0 | AB10: 0 | AC10: 0 | AD10: 0 | AE10: 0 | AF10: =I10+J10+N10+O10+S10+T10+U10+Y10+Z10+AA10+AB10+AC10+AD10 -> 16 | AG10: =14.5-AF10 -> -1.5 | AH10: =14.5-AG10 -> 16
A11: 8 | B11: S | D11: Lekganyane | E11: Molatela | F11: Yes | G11: In class | I11: 2 | J11: 2 | K11: Yes | L11: In class | N11: 2 | O11: 2 | P11: Yes | Q11: In class | S11: 2 | T11: 2 | U11: 2 | V11: Yes | W11: In class | Y11: 1 | Z11: 2 | AA11: 0 | AB11: 0 | AC11: 0 | AD11: 0 | AE11: 0 | AF11: =I11+J11+N11+O11+S11+T11+U11+Y11+Z11+AA11+AB11+AC11+AD11 -> 17 | AG11: =14.5-AF11 -> -2.5 | AH11: =14.5-AG11 -> 17
A12: 9 | B12: S | D12: Lengoati | E12: Phumelela | F12: Yes | G12: In class | I12: 2 | J12: 2 | K12: Yes | L12: In class | M12: Busy on her phone | N12: 2 | O12: 2 | P12: Yes | Q12: In class | S12: 2 | T12: 2 | U12: 2 | V12: Yes | W12: In class | Y12: 2 | Z12: 2 | AA12: 0 | AB12: 0 | AC12: 0 | AD12: 0 | AE12: 0 | AF12: =I12+J12+N12+O12+S12+T12+U12+Y12+Z12+AA12+AB12+AC12+AD12 -> 18 | AG12: =14.5-AF12 -> -3.5 | AH12: =14.5-AG12 -> 18
A13: 10 | B13: S | D13: Lepyana | E13: Nyaduwa | F13: Yes | G13: In class | I13: 1.5 | J13: 2 | K13: Yes | L13: In class | N13: 1 | O13: 2 | P13: Yes | Q13: In class | S13: 2 | T13: 2 | U13: 2 | V13: No | W13: Absent | Y13: 2 | Z13: 2 | AA13: 0 | AB13: 0 | AC13: 0 | AD13: 0 | AE13: 1 | AF13: =I13+J13+N13+O13+S13+T13+U13+Y13+Z13+AA13+AB13+AC13+AD13 -> 16.5 | AG13: =14.5-AF13 -> -2 | AH13: =14.5-AG13 -> 16.5
A14: 11 | B14: S | D14: Maake | E14: Lethabo | F14: Yes | G14: In class | I14: 1.5 | J14: 2 | K14: Yes | L14: In class | N14: 2 | O14: 2 | P14: Yes | Q14: In class | S14: 1.5 | T14: 2 | U14: 2 | V14: Yes | W14: In class | Y14: 2 | Z14: 2 | AA14: 0 | AB14: 0 | AC14: 0 | AD14: 0 | AE14: 0 | AF14: =I14+J14+N14+O14+S14+T14+U14+Y14+Z14+AA14+AB14+AC14+AD14 -> 17 | AG14: =14.5-AF14 -> -2.5 | AH14: =14.5-AG14 -> 17
A15: 12 | B15: S | D15: Magwasha | E15: Tshimangadzo | F15: Yes | G15: In class | I15: 2 | J15: 2 | K15: Yes | L15: In class | N15: 2 | O15: 2 | P15: Yes | Q15: In class | S15: 2 | T15: 2 | U15: 2 | V15: Yes | W15: In class | Y15: 2 | Z15: 2 | AA15: 1.5 | AB15: 0 | AC15: 0 | AD15: 0 | AE15: 0 | AF15: =I15+J15+N15+O15+S15+T15+U15+Y15+Z15+AA15+AB15+AC15+AD15 -> 19.5 | AG15: =14.5-AF15 -> -5 | AH15: =14.5-AG15 -> 19.5
A16: 13 | B16: S | D16: Makhabane | E16: Josephina | F16: Yes | G16: In class | I16: 0 | J16: 2 | K16: Yes | L16: In class | M16: Not paying attention, busy on her phone | N16: 2 | O16: 2 | P16: Yes | Q16: In class | S16: 1.5 | T16: 2 | U16: 2 | V16: Yes | W16: In class | Y16: 2 | Z16: 2 | AA16: 2 | AB16: 0 | AC16: 0 | AD16: 0 | AE16: 0 | AF16: =I16+J16+N16+O16+S16+T16+U16+Y16+Z16+AA16+AB16+AC16+AD16 -> 17.5 | AG16: =14.5-AF16 -> -3 | AH16: =14.5-AG16 -> 17.5
A17: 14 | B17: S | D17: Makhafola | E17: Kamogelo | F17: Yes | G17: In class | I17: 1.5 | J17: 2 | K17: Yes | L17: In class | N17: 1.5 | O17: 2 | P17: Yes | Q17: In class | S17: 2 | T17: 2 | U17: 2 | V17: Yes | W17: In class | Y17: 2 | Z17: 2 | AA17: 2 | AB17: 0 | AC17: 0 | AD17: 0 | AE17: 0 | AF17: =I17+J17+N17+O17+S17+T17+U17+Y17+Z17+AA17+AB17+AC17+AD17 -> 19 | AG17: =14.5-AF17 -> -4.5 | AH17: =14.5-AG17 -> 19
A18: 15 | B18: S | D18: Makhafola | E18: Lerato | F18: Yes | G18: In class | I18: 2 | J18: 2 | K18: Yes | L18: In class | N18: 2 | O18: 2 | P18: Yes | Q18: In class | S18: 2 | T18: 2 | U18: 2 | V18: Yes | W18: In class | Y18: 1 | Z18: 2 | AA18: 0.5 | AB18: 0 | AC18: 0 | AD18: 0 | AE18: 0 | AF18: =I18+J18+N18+O18+S18+T18+U18+Y18+Z18+AA18+AB18+AC18+AD18 -> 17.5 | AG18: =14.5-AF18 -> -3 | AH18: =14.5-AG18 -> 17.5
A19: 16 | B19: S | D19: Masemola | E19: Gopolang | F19: Yes | G19: In class | I19: 0 | J19: 2 | K19: Yes | L19: In class | N19: 1.5 | O19: 2 | P19: Yes | Q19: In class | S19: 1 | T19: 2 | U19: 2 | V19: Yes | W19: In class | Y19: 2 | Z19: 2 | AA19: 2 | AB19: 0 | AC19: 0 | AD19: 0 | AE19: 0 | AF19: =I19+J19+N19+O19+S19+T19+U19+Y19+Z19+AA19+AB19+AC19+AD19 -> 16.5 | AG19: =14.5-AF19 -> -2 | AH19: =14.5-AG19 -> 16.5
A20: 17 | B20: S | D20: Mangane | E20: Lebogang | F20: Yes | G20: In class | I20: 1.5 | J20: 2 | K20: Yes | L20: In class | N20: 1.5 | O20: 0 | P20: Yes | Q20: In class | S20: 0.5 | T20: 2 | U20: 0 | V20: Yes | W20: In class | Y20: 2 | Z20: 2 | AA20: 1.5 | AB20: 0 | AC20: 0 | AD20: 0 | AE20: 0 | AF20: =I20+J20+N20+O20+S20+T20+U20+Y20+Z20+AA20+AB20+AC20+AD20 -> 13 | AG20: =14.5-AF20 -> 1.5 | AH20: =14.5-AG20 -> 13
A21: 18 | B21: S | D21: Mashapa | E21: Morongwa | F21: Yes | G21: In class | I21: 2 | J21: 2 | K21: Yes | L21: In class | N21: 0 | O21: 2 | P21: No | Q21: Absent | S21: 2 | T21: 2 | U21: 2 | V21: Yes | W21: In class | Y21: 2 | Z21: 2 | AA21: 2 | AB21: 0 | AC21: 0 | AD21: 0 | AE21: 1 | AF21: =I21+J21+N21+O21+S21+T21+U21+Y21+Z21+AA21+AB21+AC21+AD21 -> 18 | AG21: =14.5-AF21 -> -3.5 | AH21: =14.5-AG21 -> 18
A22: 19 | B22: S | D22: Mbatha | E22: Anele | F22: Yes | G22: In class | I22: 2 | J22: 2 | K22: Yes | L22: In class | N22: 2 | O22: 2 | P22: Yes | Q22: In class | S22: 1.5 | T22: 2 | U22: 2 | V22: No | W22: Absent | Y22: 2 | Z22: 2 | AA22: 0 | AB22: 0 | AC22: 0 | AD22: 0 | AE22: 1 | AF22: =I22+J22+N22+O22+S22+T22+U22+Y22+Z22+AA22+AB22+AC22+AD22 -> 17.5 | AG22: =14.5-AF22 -> -3 | AH22: =14.5-AG22 -> 17.5
A23: 20 | B23: S | D23: Mhlongo | E23: Floyd | F23: Yes | G23: In class | I23: 2 | J23: 2 | K23: Yes | L23: In class | N23: 2 | O23: 2 | P23: Yes | Q23: In class | S23: 2 | T23: 2 | U23: 2 | V23: Yes | W23: In class | Y23: 2 | Z23: 2 | AA23: 2 | AB23: 0 | AC23: 0 | AD23: 0 | AE23: 0 | AF23: =I23+J23+N23+O23+S23+T23+U23+Y23+Z23+AA23+AB23+AC23+AD23 -> 20 | AG23: =14.5-AF23 -> -5.5 | AH23: =14.5-AG23 -> 20
A24: 21 | B24: S | D24: Mndwetywa | E24: Yamkelani | F24: No | G24: Absent | I24: 2 | J24: 2 | K24: Yes | L24: In class | N24: 1 | O24: 2 | P24: Yes | Q24: In class | S24: 2 | T24: 0 | U24: 2 | V24: Yes | W24: In class | X24: Left class at 17:20 | Y24: 1 | Z24: 2 | AA24: 0.5 | AB24: 0 | AC24: 0 | AD24: 0 | AE24: 1 | AF24: =I24+J24+N24+O24+S24+T24+U24+Y24+Z24+AA24+AB24+AC24+AD24 -> 14.5 | AG24: =14.5-AF24 -> 0 | AH24: =14.5-AG24 -> 14.5
A25: 22 | B25: S | D25: Moema | E25: Boitshoko | F25: Yes | G25: In class | I25: 0 | J25: 2 | K25: Yes | L25: In class | N25: 2 | O25: 2 | P25: Yes | Q25: In class | S25: 2 | T25: 2 | U25: 2 | V25: Yes | W25: In class | Y25: 2 | Z25: 2 | AA25: 2 | AB25: 0 | AC25: 0 | AD25: 0 | AE25: 0 | AF25: =I25+J25+N25+O25+S25+T25+U25+Y25+Z25+AA25+AB25+AC25+AD25 -> 18 | AG25: =14.5-AF25 -> -3.5 | AH25: =14.5-AG25 -> 18
A26: 23 | B26: S | D26: Molaletsa | E26: Karabo | F26: Yes | G26: In class | I26: 2 | J26: 2 | K26: Yes | L26: In class | N26: 2 | O26: 2 | P26: Yes | Q26: In class | S26: 2 | T26: 0 | U26: 2 | V26: Yes | W26: In class | Y26: 2 | Z26: 2 | AA26: 2 | AB26: 0 | AC26: 0 | AD26: 0 | AE26: 0 | AF26: =I26+J26+N26+O26+S26+T26+U26+Y26+Z26+AA26+AB26+AC26+AD26 -> 18 | AG26: =14.5-AF26 -> -3.5 | AH26: =14.5-AG26 -> 18
A27: 24 | B27: S | D27: Monametsi | E27: Refilwe | F27: Yes | G27: In class | I27: 1 | J27: 2 | K27: Yes | L27: In class | N27: 2 | O27: 2 | P27: Yes | Q27: In class | S27: 0.5 | T27: 2 | U27: 2 | V27: Yes | W27: In class | Y27: 2 | Z27: 2 | AA27: 2 | AB27: 0 | AC27: 0 | AD27: 0 | AE27: 0 | AF27: =I27+J27+N27+O27+S27+T27+U27+Y27+Z27+AA27+AB27+AC27+AD27 -> 17.5 | AG27: =14.5-AF27 -> -3 | AH27: =14.5-AG27 -> 17.5
A28: 25 | B28: S | D28: More | E28: Molebatsi | F28: No | G28: Reported absent | I28: 0 | J28: 0 | K28: Yes | L28: In class | N28: 2 | O28: 2 | P28: Yes | Q28: In class | S28: 2 | T28: 2 | U28: 2 | V28: Yes | W28: In class | Y28: 0 | Z28: 2 | AA28: 2 | AB28: 0 | AC28: 0 | AD28: 0 | AE28: 1 | AF28: =I28+J28+N28+O28+S28+T28+U28+Y28+Z28+AA28+AB28+AC28+AD28 -> 14 | AG28: =14.5-AF28 -> 0.5 | AH28: =14.5-AG28 -> 14
A29: 26 | B29: S | D29: Motimele | E29: Tshegofatso | F29: Yes | G29: In class | I29: 2 | J29: 2 | K29: Yes | L29: In class | N29: 2 | O29: 2 | P29: Yes | Q29: In class | S29: 2 | T29: 0 | U29: 2 | V29: Yes | W29: In class | Y29: 2 | Z29: 2 | AA29: 2 | AB29: 0 | AC29: 0 | AD29: 0 | AE29: 0 | AF29: =I29+J29+N29+O29+S29+T29+U29+Y29+Z29+AA29+AB29+AC29+AD29 -> 18 | AG29: =14.5-AF29 -> -3.5 | AH29: =14.5-AG29 -> 18
